<?xml version="1.0"?>
<!-- =================================================================================== -->
<!-- |    This document was autogenerated by xacro from
/home/luigi/walter_simulado/install/modelo2/share/walter_description/urdf/robot.urdf.xacro | -->
<!-- |    EDITING THIS FILE BY HAND IS NOT RECOMMENDED                                 | -->
<!-- =================================================================================== -->
<robot name="Walter" xmlns:xacro="http://www.ros.org/wiki/xacro">
  <!-- Gazebo plugings -->
  <gazebo reference="fijos_inferior">
    <mu1>0.2</mu1>
    <mu2>0.2</mu2>
    <selfCollide>true</selfCollide>
    <gravity>true</gravity>
    <material>Gazebo/White</material>
    <preserveFixedJoint>true</preserveFixedJoint>
  </gazebo>
  <gazebo reference="base">
</gazebo>

  <gazebo reference="rueda">
    <mu1>0.1</mu1>
    <mu2>0.1</mu2>
    <kp>500.0</kp>
    <kd>10.0</kd>
    <minDepth>0.001</minDepth>
    <maxVel>0.1</maxVel>
    <fdir1>1 0 0</fdir1>
    <material>Gazebo/Yellow</material>
  </gazebo>
  <gazebo reference="rueda_2">
    <mu1>0.1</mu1>
    <mu2>0.1</mu2>
    <kp>500.0</kp>
    <kd>10.0</kd>
    <minDepth>0.001</minDepth>
    <maxVel>0.1</maxVel>
    <fdir1>1 0 0</fdir1>
    <material>Gazebo/Yellow</material>
  </gazebo>

  <gazebo>
    <plugin filename="libgazebo_ros_control.so" name="gazebo_ros_control">
      <robotNamespace>/</robotNamespace>
      <controlPeriod>20</controlPeriod>
    </plugin>
  </gazebo>
  <gazebo>
    <plugin filename="libgazebo_ros_joint_state_publisher.so"
      name="gazebo_ros_joint_state_publisher">
      <update_rate>20</update_rate>
      <joint_name>fijos_to_rueda</joint_name>
      <joint_name>fijos_to_rueda_2</joint_name>
      <joint_name>base_to_fijos_inferior</joint_name>
    </plugin>
  </gazebo>
  <gazebo>
    <plugin filename="libgazebo_ros_joint_pose_trajectory.so"
      name="gazebo_ros_joint_pose_trajectory">
      <update_rate>20</update_rate>
    </plugin>
  </gazebo>

  <gazebo>
    <plugin filename="libgazebo_ros_diff_drive.so" name="diff_drive">
      <!-- Wheel Information -->
      <left_joint>fijos_to_rueda_2</left_joint>
      <right_joint>fijos_to_rueda</right_joint>
      <wheel_separation>0.46</wheel_separation>
      <wheel_diameter>0.17</wheel_diameter>
      <!-- Limits -->
      <max_wheel_torque>200</max_wheel_torque>
      <max_wheel_acceleration>10.0</max_wheel_acceleration>
      <!-- Output -->
      <odometryTopic>odom</odometryTopic>
      <odometry_frame>odom</odometry_frame>
      <commandTopic>cmd_vel</commandTopic>
      <robot_base_frame>base</robot_base_frame>
      <publish_odom>true</publish_odom>
      <publish_odom_tf>true</publish_odom_tf>
      <publish_wheel_tf>true</publish_wheel_tf>
    </plugin>
  </gazebo>

  <!--URDF
  Componentes-->
  <link name="base">
  </link>

  <link name="fijos_inferior">
    <!-- Eje -->
    <visual>
      <origin rpy="0 0 1.57" xyz="0 0 0.035" />
      <geometry>
        <mesh filename="package://walter_description/urdf/eje.stl" scale="1 1 1" />
      </geometry>
      <material name="eje_material">
        <color rgba="0.62 0.81 0.93 1.0" />
      </material>
    </visual>
    <collision>
      <origin rpy="0 0 1.57" xyz="0 0 0.035" />
      <geometry>
        <mesh filename="package://walter_description/urdf/eje.stl" scale="1 1 1" />
      </geometry>
    </collision>
    <!-- Eje Caster -->
    <visual>
      <origin rpy="0 0 0" xyz="0 0.245 0" />
      <geometry>
        <mesh filename="package://walter_description/urdf/eje_caster.stl" scale="1 1 1" />
      </geometry>
      <material name="eje_caster_material">
        <color rgba="0.62 0.81 0.93 1.0" />
      </material>
    </visual>
    <collision>
      <origin rpy="0 0 0" xyz="0 0.245 0" />
      <geometry>
        <mesh filename="package://walter_description/urdf/eje_caster.stl" scale="1 1 1" />
      </geometry>
    </collision>
    <!-- Llanta Caster 2 (trasera derecha e izquierda) -->
    <visual>
      <origin rpy="1.57 1.57 0" xyz="0.015 -0.275 -0.055" />
      <geometry>
        <mesh filename="package://walter_description/urdf/llanta_caster2.stl" scale="1 1 1" />
      </geometry>
      <material name="llanta_caster2_material">
        <color rgba="0.65 0.65 0.65 1.0" />
      </material>
    </visual>
    <collision>
      <origin rpy="1.57 1.57 0" xyz="0.015 -0.27 -0.055" />
      <geometry>
        <mesh filename="package://walter_description/urdf/llanta_caster2.stl" scale="1 1 1" />
      </geometry>
    </collision>
    <visual>
      <origin rpy="1.57 1.57 0" xyz="0.015 0.215 -0.055" />
      <geometry>
        <mesh filename="package://walter_description/urdf/llanta_caster2.stl" scale="1 1 1" />
      </geometry>
      <material name="llanta_caster2_material">
        <color rgba="0.65 0.65 0.65 1.0" />
      </material>
    </visual>
    <collision>
      <origin rpy="1.57 1.57 0" xyz="0.015 0.21 -0.055" />
      <geometry>
        <mesh filename="package://walter_description/urdf/llanta_caster2.stl" scale="1 1 1" />
      </geometry>
    </collision>
    <!-- Llanta Caster 1 (delantera derecha e izquierda) -->
    <visual>
      <origin rpy="1.57 -1.57 0" xyz="-0.055 -0.275 -0.0046" />
      <geometry>
        <mesh filename="package://walter_description/urdf/llanta_caster1.stl" scale="1 1 1" />
      </geometry>
      <material name="llanta_caster1_material">
        <color rgba="0.65 0.65 0.65 1.0" />
      </material>
    </visual>
    <collision>
      <origin rpy="1.57 -1.57 0" xyz="-0.055 -0.275 -0.0046" />
      <geometry>
        <mesh filename="package://walter_description/urdf/llanta_caster1.stl" scale="1 1 1" />
      </geometry>
    </collision>
    <visual>
      <origin rpy="1.57 -1.57 0" xyz="-0.055 0.215 -0.0046" />
      <geometry>
        <mesh filename="package://walter_description/urdf/llanta_caster1.stl" scale="1 1 1" />
      </geometry>
      <material name="llanta_caster1_material">
        <color rgba="0.65 0.65 0.65 1.0" />
      </material>
    </visual>
    <collision>
      <origin rpy="1.57 -1.57 0" xyz="-0.055 0.215 -0.0046" />
      <geometry>
        <mesh filename="package://walter_description/urdf/llanta_caster1.stl" scale="1 1 1" />
      </geometry>
    </collision>
    <inertial>
      <origin rpy="0 0 0" xyz="0 0 0.0" />
      <mass value="5.69938813" />
      <inertia ixx="0.105494" ixy="0.0" ixz="0.0" iyy="9.3" iyz="-1.0" izz="2.45" />
    </inertial>


  </link>
  <!-- Base inferior -->
  <visual>
    <origin rpy="0 0 0" xyz="0 0 0" />
    <geometry>
      <mesh filename="package://walter_description/urdf/base.stl" scale="1 1 1" />
    </geometry>
    <material name="base_material">
      <color rgba="0.90 0.90 0.90 1.0" />
    </material>
  </visual>
  <collision>
    <origin rpy="0 0 0" xyz="0 0 0" />
    <geometry>
      <mesh filename="package://walter_description/urdf/base.stl" scale="1 1 1" />
    </geometry>
  </collision>
  <!-- Base superior -->
  <visual>
    <origin rpy="0 0 0" xyz="0 0 0.13" />
    <geometry>
      <mesh filename="package://walter_description/urdf/base.stl" scale="1 1 1" />
    </geometry>
    <material name="base_material">
      <color rgba="0.90 0.90 0.90 1.0" />
    </material>
  </visual>
  <collision>
    <origin rpy="0 0 0" xyz="0 0 0.13" />
    <geometry>
      <mesh filename="package://walter_description/urdf/base.stl" scale="1 1 1" />
    </geometry>
  </collision>
  <!-- Tope -->
  <visual>
    <origin rpy="0 0 0" xyz="0 0 0.010" />
    <geometry>
      <mesh filename="package://walter_description/urdf/tope.stl" scale="1 1 1" />
    </geometry>
    <material name="tope_material">
      <color rgba="0.615 0.81 0.93 1.0" />
    </material>
  </visual>
  <collision>
    <origin rpy="0 0 0" xyz="0 0 0.010" />
    <geometry>
      <mesh filename="package://walter_description/urdf/tope.stl" scale="1 1 1" />
    </geometry>
  </collision>
  <!-- Cabeza -->
  <visual>
    <origin rpy="0 0 1.57" xyz="0 0.035 1.035" />
    <geometry>
      <mesh filename="package://walter_description/urdf/cabeza.stl" scale="1 1 1" />
    </geometry>
    <material name="cabeza_material">
      <color rgba="0.901 0.901 0.901 1.0" />
    </material>
  </visual>
  <collision>
    <origin rpy="0 0 1.57" xyz="0 0.035 1.035" />
    <geometry>
      <mesh filename="package://walter_description/urdf/cabeza.stl" scale="1 1 1" />
    </geometry>
  </collision>
  <!-- Brazos -->
  <visual>
    <origin rpy="0 -1.504 1.57" xyz="0.19 0 0.78" />
    <geometry>
      <mesh filename="package://walter_description/urdf/brazo1.stl" scale="1 1 1" />
    </geometry>
    <material name="brazo1_material">
      <color rgba="0.901 0.901 0.901 1.0" />
    </material>
  </visual>
  <collision>
    <origin rpy="0 -1.50 1.57" xyz="0.19 0 0.779" />
    <geometry>
      <mesh filename="package://walter_description/urdf/brazo1.stl" scale="1 1 1" />
    </geometry>
  </collision>
  <visual>
    <origin rpy="3.141 1.456 1.57" xyz="-0.19 0 0.779" />
    <geometry>
      <mesh filename="package://walter_description/urdf/brazo1.stl" scale="1 1 1" />
    </geometry>
    <material name="brazo1_material">
      <color rgba="0.901 0.901 0.901 1.0" />
    </material>
  </visual>
  <collision>
    <origin rpy="3.141 1.45 1.57" xyz="-0.19 0 0.779" />
    <geometry>
      <mesh filename="package://walter_description/urdf/brazo1.stl" scale="1 1 1" />
    </geometry>
  </collision>
  <!-- Torso -->
  <visual>
    <origin rpy="0 0 1.57" xyz="0 0 0.14" />
    <geometry>
      <mesh filename="package://walter_description/urdf/torso.stl" scale="1 1 1" />
    </geometry>
    <material name="torso_material">
      <color rgba="0.901 0.901 0.901 1.0" />
    </material>
  </visual>
  <collision>
    <origin rpy="0 0 1.57" xyz="0 0 0.14" />
    <geometry>
      <mesh filename="package://walter_description/urdf/torso.stl" scale="1 1 1" />
    </geometry>
  </collision>
  <!-- Pecho -->
  <visual>
    <origin rpy="0 0 1.57" xyz="0 0 0.765" />
    <geometry>
      <mesh filename="package://walter_description/urdf/pecho.stl" scale="1 1 1" />
    </geometry>
    <material name="pecho_material">
      <color rgba="0.901 0.901 0.901 1.0" />
    </material>
  </visual>
  <collision>
    <origin rpy="0 0 1.57" xyz="0 0 0.765" />
    <geometry>
      <mesh filename="package://walter_description/urdf/pecho.stl" scale="1 1 1" />
    </geometry>
  </collision>
  <!-- Inertial -->
  <inertial>
    <origin rpy="0 0 0" xyz="0 0.00078 0.50" />
    <mass value="131.422" />
    <inertia ixx="9.3" ixy="1.0" ixz="1.0" iyy="9.3" iyz="-1.0" izz="2.45" />
  </inertial>
  </link>

  <!-- Rueda -->
  <link name="rueda">
    <visual>
      <origin rpy="1.570 0 0" xyz="0 0 -0.015" />
      <geometry>
        <mesh filename="package://walter_description/urdf/llanta.stl" scale="1 1 1" />
      </geometry>
      <material name="llanta_material">
        <color rgba="0.647 0.647 0.647 1.0" />
      </material>
    </visual>
    <collision>
      <origin rpy="1.570 0 0" xyz="0 0 -0.015" />
      <geometry>
        <mesh filename="package://walter_description/urdf/llanta.stl" scale="1 1 1" />
      </geometry>
    </collision>
    <visual>
      <origin rpy="1.5707 0 0" xyz="0 0 -0.015" />
      <geometry>
        <mesh filename="package://walter_description/urdf/aro.stl" scale="1 1 1" />
      </geometry>
      <material name="aro_material">
        <color rgba="0.980 0.71 0.0039 1.0" />
      </material>
    </visual>
    <collision>
      <origin rpy="1.570 0 0" xyz="0 0 -0.015" />
      <geometry>
        <mesh filename="package://walter_description/urdf/aro.stl" scale="1 1 1" />
      </geometry>
    </collision>
    <inertial>
      <origin rpy="0 0 0" xyz="0 0 -0.015000000000000013323" />
      <mass value="0.93" />
      <inertia ixx="0.005" ixy="0" ixz="0" iyy="0.005" iyz="0" izz="0.005" />
    </inertial>
  </link>


  <!-- Rueda2 -->
  <link name="rueda_2">
    <visual>
      <origin rpy="-1.57 0 0" xyz="0 0 -0.015" />
      <geometry>
        <mesh filename="package://walter_description/urdf/llanta.stl" scale="1 1 1" />
      </geometry>
      <material name="llanta_material">
        <color rgba="0.65 0.65 0.65 1.0" />
      </material>
    </visual>
    <collision>
      <origin rpy="-1.57 0 0" xyz="0 0 -0.015" />
      <geometry>
        <mesh filename="package://walter_description/urdf/llanta.stl" scale="1 1 1" />
      </geometry>
    </collision>
    <visual>
      <origin rpy="-1.57 0 0" xyz="0 0 -0.015" />
      <geometry>
        <mesh filename="package://walter_description/urdf/aro.stl" scale="1 1 1" />
      </geometry>
      <material name="aro_material">
        <color rgba="0.98 0.71 0.0039 1.0" />
      </material>
    </visual>
    <collision>
      <origin rpy="-1.57 0 0" xyz="0 0 -0.015" />
      <geometry>
        <mesh filename="package://walter_description/urdf/aro.stl" scale="1 1 1" />
      </geometry>
    </collision>
    <inertial>
      <origin rpy="0 0 0" xyz="0 0 -0.015000000000000009853" />
      <mass value="0.93" />
      <inertia ixx="0.005" ixy="0" ixz="0" iyy="0.005" iyz="0" izz="0.005" />
    </inertial>
  </link>

  <!-- Joints -->
  <joint name="base_to_fijos_inferior" type="fixed">
    <parent link="base" />
    <child link="fijos_inferior" />
    <origin rpy="0 0 0" xyz="0 1 0" />
    <axis xyz="0 0 0" />
  </joint>

  <joint name="fijos_to_rueda" type="continuous">
    <parent link="fijos_inferior" />
    <child link="rueda" />
    <origin rpy="0 1.5708 0" xyz="0.23 0 0.035" />
    <axis xyz="0 0 1" />
    <limit effort="10000" velocity="1000" />
    <joint_properties damping="1.0" friction="1.0" />
  </joint>

  <joint name="fijos_to_rueda_2" type="continuous">
    <parent link="fijos_inferior" />
    <child link="rueda_2" />
    <origin rpy="0 -1.5708 0" xyz="-0.23 0 0.035" />
    <axis xyz="0 0 -1" />
    <limit effort="10000" velocity="1000" />
    <joint_properties damping="1.0" friction="1.0" />
  </joint>

</robot>